{"timestamp": "2025-09-07T17:42:08.948835", "error_id": "18c6a5a2-ab0e-47ea-881f-21f4bdcb62e9", "category": "network", "severity": "low", "message": "Test info message #1", "details": "This is a test error generated for testing purposes. Error number: 1, Severity: low", "context": {"test_number": 1, "generated_by": "test_app", "component": "error_test"}, "exception_type": null, "exception_message": null, "recovery_attempted": false, "recovery_successful": false, "retry_count": 0}
{"timestamp": "2025-09-07T17:42:11.641777", "error_id": "5d628fa9-714c-4dcf-a7ec-caa5a6615ea0", "category": "proxy", "severity": "medium", "message": "Test warning message #2", "details": "This is a test error generated for testing purposes. Error number: 2, Severity: medium", "context": {"test_number": 2, "generated_by": "test_app", "component": "error_test"}, "exception_type": null, "exception_message": null, "recovery_attempted": false, "recovery_successful": false, "retry_count": 0}
{"timestamp": "2025-09-07T17:42:14.754112", "error_id": "4bf306c0-7a9e-4365-a51c-9ef66abd99d8", "category": "system", "severity": "low", "message": "Test info message #3", "details": "This is a test error generated for testing purposes. Error number: 3, Severity: low", "context": {"test_number": 3, "generated_by": "test_app", "component": "error_test"}, "exception_type": null, "exception_message": null, "recovery_attempted": false, "recovery_successful": false, "retry_count": 0}
{"timestamp": "2025-09-07T17:42:15.714091", "error_id": "8450ddc6-5af0-47db-bf24-9c51645d1007", "category": "pac_validation", "severity": "low", "message": "Test info message #4", "details": "This is a test error generated for testing purposes. Error number: 4, Severity: low", "context": {"test_number": 4, "generated_by": "test_app", "component": "error_test"}, "exception_type": null, "exception_message": null, "recovery_attempted": false, "recovery_successful": false, "retry_count": 0}
{"timestamp": "2025-09-07T17:42:16.554027", "error_id": "23242160-28c9-40d3-aaf6-cbeb004cb269", "category": "network", "severity": "low", "message": "Test info message #5", "details": "This is a test error generated for testing purposes. Error number: 5, Severity: low", "context": {"test_number": 5, "generated_by": "test_app", "component": "error_test"}, "exception_type": null, "exception_message": null, "recovery_attempted": false, "recovery_successful": false, "retry_count": 0}
{"timestamp": "2025-09-07T17:42:18.144787", "error_id": "ccc5ad76-d66e-48f8-953d-4ac6b1e969bd", "category": "proxy", "severity": "high", "message": "Test error message #6", "details": "This is a test error generated for testing purposes. Error number: 6, Severity: high", "context": {"test_number": 6, "generated_by": "test_app", "component": "error_test"}, "exception_type": null, "exception_message": null, "recovery_attempted": false, "recovery_successful": false, "retry_count": 0}
{"timestamp": "2025-09-07T17:42:19.666327", "error_id": "baffc1d4-270d-4f0c-9766-b8939dadf785", "category": "system", "severity": "critical", "message": "Test critical error #7", "details": "This is a test error generated for testing purposes. Error number: 7, Severity: critical", "context": {"test_number": 7, "generated_by": "test_app", "component": "error_test"}, "exception_type": null, "exception_message": null, "recovery_attempted": false, "recovery_successful": false, "retry_count": 0}
{"timestamp": "2025-09-07T17:42:21.841730", "error_id": "eee365b4-10ed-4fc9-af64-8c9fb87c9da6", "category": "pac_validation", "severity": "medium", "message": "PAC validation failed #8", "details": "Test error for category pac_validation", "context": {"test_category": "pac_validation", "test_number": 8}, "exception_type": null, "exception_message": null, "recovery_attempted": false, "recovery_successful": false, "retry_count": 0}
{"timestamp": "2025-09-07T17:42:23.071820", "error_id": "53b0eda8-59cc-44ed-ad76-c1fe885126c7", "category": "network", "severity": "high", "message": "Network connection error #9", "details": "Test error for category network", "context": {"test_category": "network", "test_number": 9}, "exception_type": null, "exception_message": null, "recovery_attempted": false, "recovery_successful": false, "retry_count": 0}
{"timestamp": "2025-09-07T17:42:24.084312", "error_id": "eb69a155-a1f8-4153-982b-8ba553fd6108", "category": "proxy", "severity": "high", "message": "Proxy service error #10", "details": "Test error for category proxy", "context": {"test_category": "proxy", "test_number": 10}, "exception_type": null, "exception_message": null, "recovery_attempted": false, "recovery_successful": false, "retry_count": 0}
{"timestamp": "2025-09-07T17:42:29.709485", "error_id": "4bf5b58f-3531-432b-84ce-9834654d15f8", "category": "proxy", "severity": "high", "message": "Proxy service error #11", "details": "Test error for category proxy", "context": {"test_category": "proxy", "test_number": 11}, "exception_type": null, "exception_message": null, "recovery_attempted": false, "recovery_successful": false, "retry_count": 0}
{"timestamp": "2025-09-07T17:42:30.691921", "error_id": "6a9ce5bb-19dd-4528-abce-6ea6f62624fa", "category": "proxy", "severity": "high", "message": "Proxy service error #12", "details": "Test error for category proxy", "context": {"test_category": "proxy", "test_number": 12}, "exception_type": null, "exception_message": null, "recovery_attempted": false, "recovery_successful": false, "retry_count": 0}
{"timestamp": "2025-09-07T17:42:32.296922", "error_id": "db6d4eb6-4916-4594-a642-b38a7da1639f", "category": "system", "severity": "high", "message": "System error #13", "details": "Test error for category system", "context": {"test_category": "system", "test_number": 13}, "exception_type": null, "exception_message": null, "recovery_attempted": false, "recovery_successful": false, "retry_count": 0}
{"timestamp": "2025-09-07T17:42:33.819034", "error_id": "c4cb3518-c9f2-4ce0-ba87-c7454de1eea6", "category": "system", "severity": "high", "message": "System error #14", "details": "Test error for category system", "context": {"test_category": "system", "test_number": 14}, "exception_type": null, "exception_message": null, "recovery_attempted": false, "recovery_successful": false, "retry_count": 0}
{"timestamp": "2025-09-07T17:42:56.191733", "error_id": "c3eb12f5-9a8a-4a09-ae4d-274402d48f3e", "category": "proxy", "severity": "high", "message": "Proxy service connection failed", "details": "Testing automatic recovery mechanisms", "context": {"recoverable": true, "test_recovery": true}, "exception_type": null, "exception_message": null, "recovery_attempted": false, "recovery_successful": false, "retry_count": 0}
{"timestamp": "2025-09-07T17:43:04.074857", "error_id": "49a30d82-631f-4fdb-8e52-502865c6903f", "category": "pac_validation", "severity": "low", "message": "Batch error #1", "details": "This is batch error number 1 of 5", "context": {"batch_test": true, "error_index": 0}, "exception_type": null, "exception_message": null, "recovery_attempted": false, "recovery_successful": false, "retry_count": 0}
{"timestamp": "2025-09-07T17:43:04.586170", "error_id": "ec3530b1-aa51-4434-979c-e69cd3095262", "category": "network", "severity": "medium", "message": "Batch error #2", "details": "This is batch error number 2 of 5", "context": {"batch_test": true, "error_index": 1}, "exception_type": null, "exception_message": null, "recovery_attempted": false, "recovery_successful": false, "retry_count": 0}
{"timestamp": "2025-09-07T17:43:05.138369", "error_id": "d258d702-89c8-4110-a4b7-1fceae38ba35", "category": "proxy", "severity": "high", "message": "Batch error #3", "details": "This is batch error number 3 of 5", "context": {"batch_test": true, "error_index": 2}, "exception_type": null, "exception_message": null, "recovery_attempted": false, "recovery_successful": false, "retry_count": 0}
{"timestamp": "2025-09-07T17:43:05.311993", "error_id": "c7df8c1d-a8bb-4e4b-821e-ace984f0d7d7", "category": "system", "severity": "high", "message": "System error #15", "details": "Test error for category system", "context": {"test_category": "system", "test_number": 15}, "exception_type": null, "exception_message": null, "recovery_attempted": false, "recovery_successful": false, "retry_count": 0}
{"timestamp": "2025-09-07T17:43:05.652026", "error_id": "6249f1ff-60b3-4908-b74e-e8b12a970373", "category": "pac_validation", "severity": "low", "message": "Batch error #4", "details": "This is batch error number 4 of 5", "context": {"batch_test": true, "error_index": 3}, "exception_type": null, "exception_message": null, "recovery_attempted": false, "recovery_successful": false, "retry_count": 0}
{"timestamp": "2025-09-07T17:43:06.205345", "error_id": "19b61658-f799-45b4-9318-3b5f1587cc74", "category": "network", "severity": "medium", "message": "Batch error #5", "details": "This is batch error number 5 of 5", "context": {"batch_test": true, "error_index": 4}, "exception_type": null, "exception_message": null, "recovery_attempted": false, "recovery_successful": false, "retry_count": 0}
{"timestamp": "2025-09-07T17:43:07.232229", "error_id": "d7f9d984-6da4-416e-b90a-015d819b8bf8", "category": "proxy", "severity": "high", "message": "Proxy service error #16", "details": "Test error for category proxy", "context": {"test_category": "proxy", "test_number": 16}, "exception_type": null, "exception_message": null, "recovery_attempted": false, "recovery_successful": false, "retry_count": 0}
